/home/sage/.pyenv/versions/3.11.5/lib/python3.11/site-packages/transformers/models/marian/tokenization_marian.py:175: UserWarning: Recommended: pip install sacremoses.
  warnings.warn("Recommended: pip install sacremoses.")
Device set to use cpu
モデルをロード中...
日英翻訳モデルをロード中...
英日翻訳モデルをロード中...
モデルのロード中にエラーが発生しました: Helsinki-NLP/opus-mt-en-ja is not a local folder and is not a valid model identifier listed on 'https://huggingface.co/models'
If this is a private repository, make sure to pass a token having permission to this repo either by logging in with `huggingface-cli login` or by passing `token=<your_token>`
Traceback (most recent call last):
  File "/home/sage/.pyenv/versions/3.11.5/lib/python3.11/site-packages/huggingface_hub/utils/_http.py", line 409, in hf_raise_for_status
    response.raise_for_status()
  File "/home/sage/.pyenv/versions/3.11.5/lib/python3.11/site-packages/requests/models.py", line 1024, in raise_for_status
    raise HTTPError(http_error_msg, response=self)
requests.exceptions.HTTPError: 401 Client Error: Unauthorized for url: https://huggingface.co/Helsinki-NLP/opus-mt-en-ja/resolve/main/config.json

The above exception was the direct cause of the following exception:

Traceback (most recent call last):
  File "/home/sage/.pyenv/versions/3.11.5/lib/python3.11/site-packages/transformers/utils/hub.py", line 424, in cached_files
    hf_hub_download(
  File "/home/sage/.pyenv/versions/3.11.5/lib/python3.11/site-packages/huggingface_hub/utils/_validators.py", line 114, in _inner_fn
    return fn(*args, **kwargs)
           ^^^^^^^^^^^^^^^^^^^
  File "/home/sage/.pyenv/versions/3.11.5/lib/python3.11/site-packages/huggingface_hub/file_download.py", line 961, in hf_hub_download
    return _hf_hub_download_to_cache_dir(
           ^^^^^^^^^^^^^^^^^^^^^^^^^^^^^^
  File "/home/sage/.pyenv/versions/3.11.5/lib/python3.11/site-packages/huggingface_hub/file_download.py", line 1068, in _hf_hub_download_to_cache_dir
    _raise_on_head_call_error(head_call_error, force_download, local_files_only)
  File "/home/sage/.pyenv/versions/3.11.5/lib/python3.11/site-packages/huggingface_hub/file_download.py", line 1596, in _raise_on_head_call_error
    raise head_call_error
  File "/home/sage/.pyenv/versions/3.11.5/lib/python3.11/site-packages/huggingface_hub/file_download.py", line 1484, in _get_metadata_or_catch_error
    metadata = get_hf_file_metadata(
               ^^^^^^^^^^^^^^^^^^^^^
  File "/home/sage/.pyenv/versions/3.11.5/lib/python3.11/site-packages/huggingface_hub/utils/_validators.py", line 114, in _inner_fn
    return fn(*args, **kwargs)
           ^^^^^^^^^^^^^^^^^^^
  File "/home/sage/.pyenv/versions/3.11.5/lib/python3.11/site-packages/huggingface_hub/file_download.py", line 1401, in get_hf_file_metadata
    r = _request_wrapper(
        ^^^^^^^^^^^^^^^^^
  File "/home/sage/.pyenv/versions/3.11.5/lib/python3.11/site-packages/huggingface_hub/file_download.py", line 285, in _request_wrapper
    response = _request_wrapper(
               ^^^^^^^^^^^^^^^^^
  File "/home/sage/.pyenv/versions/3.11.5/lib/python3.11/site-packages/huggingface_hub/file_download.py", line 309, in _request_wrapper
    hf_raise_for_status(response)
  File "/home/sage/.pyenv/versions/3.11.5/lib/python3.11/site-packages/huggingface_hub/utils/_http.py", line 459, in hf_raise_for_status
    raise _format(RepositoryNotFoundError, message, response) from e
huggingface_hub.errors.RepositoryNotFoundError: 401 Client Error. (Request ID: Root=1-681bbb05-202d628115c8af4429e0e3af;f5f83bfa-668f-4550-8b2e-b310d3f14f34)

Repository Not Found for url: https://huggingface.co/Helsinki-NLP/opus-mt-en-ja/resolve/main/config.json.
Please make sure you specified the correct `repo_id` and `repo_type`.
If you are trying to access a private or gated repo, make sure you are authenticated. For more details, see https://huggingface.co/docs/huggingface_hub/authentication
Invalid username or password.

The above exception was the direct cause of the following exception:

Traceback (most recent call last):
  File "/home/sage/worker/espnet/translate-summary.py", line 20, in <module>
    translator_en_to_ja = pipeline("translation", model="Helsinki-NLP/opus-mt-en-ja", device="cpu")
                          ^^^^^^^^^^^^^^^^^^^^^^^^^^^^^^^^^^^^^^^^^^^^^^^^^^^^^^^^^^^^^^^^^^^^^^^^^
  File "/home/sage/.pyenv/versions/3.11.5/lib/python3.11/site-packages/transformers/pipelines/__init__.py", line 812, in pipeline
    resolved_config_file = cached_file(
                           ^^^^^^^^^^^^
  File "/home/sage/.pyenv/versions/3.11.5/lib/python3.11/site-packages/transformers/utils/hub.py", line 266, in cached_file
    file = cached_files(path_or_repo_id=path_or_repo_id, filenames=[filename], **kwargs)
           ^^^^^^^^^^^^^^^^^^^^^^^^^^^^^^^^^^^^^^^^^^^^^^^^^^^^^^^^^^^^^^^^^^^^^^^^^^^^^
  File "/home/sage/.pyenv/versions/3.11.5/lib/python3.11/site-packages/transformers/utils/hub.py", line 456, in cached_files
    raise OSError(
OSError: Helsinki-NLP/opus-mt-en-ja is not a local folder and is not a valid model identifier listed on 'https://huggingface.co/models'
If this is a private repository, make sure to pass a token having permission to this repo either by logging in with `huggingface-cli login` or by passing `token=<your_token>`
